[2025-02-04 13:17:54,889](run_tvsrv) Ошибка Инфотабло: возможно нет связи? HTTPConnectionPool(host='127.0.0.1', port=32109): Max retries exceeded with url: /ticket?p=7&t=%D0%9B3 (Caused by NewConnectionError('<urllib3.connection.HTTPConnection object at 0x7f80209f2a00>: Failed to establish a new connection: [Errno 111] Connection refused')). 
[2025-02-04 13:18:04,091](run_tvsrv) Ошибка Инфотабло: возможно нет связи? HTTPConnectionPool(host='127.0.0.1', port=32109): Max retries exceeded with url: /ticket?p=7&t=---- (Caused by NewConnectionError('<urllib3.connection.HTTPConnection object at 0x7f802098e760>: Failed to establish a new connection: [Errno 111] Connection refused')). 
[2025-02-04 13:18:13,431](run_tvsrv) Ошибка Инфотабло: возможно нет связи? HTTPConnectionPool(host='127.0.0.1', port=32109): Max retries exceeded with url: /ticket?p=7&t=%D0%A07 (Caused by NewConnectionError('<urllib3.connection.HTTPConnection object at 0x7f802098e310>: Failed to establish a new connection: [Errno 111] Connection refused')). 
[2025-02-04 13:20:08,990](main) Filepid(/run/user/1000/srv12.pid) exists, but the process is not started! Delete filepid
[2025-02-04 13:20:14,413](run_tvsrv) Ошибка Инфотабло: возможно нет связи? HTTPConnectionPool(host='127.0.0.1', port=32109): Max retries exceeded with url: /ticket?p=7&t=%D0%A07 (Caused by NewConnectionError('<urllib3.connection.HTTPConnection object at 0x7f8c0adb87f0>: Failed to establish a new connection: [Errno 111] Connection refused')). 
[2025-02-04 13:20:19,330](run_tvsrv) Ошибка Инфотабло: возможно нет связи? HTTPConnectionPool(host='127.0.0.1', port=32109): Max retries exceeded with url: /ticket?p=7&t=---- (Caused by NewConnectionError('<urllib3.connection.HTTPConnection object at 0x7f8c0ad9e7f0>: Failed to establish a new connection: [Errno 111] Connection refused')). 
[2025-02-04 13:20:20,862](run_tvsrv) Ошибка Инфотабло: возможно нет связи? HTTPConnectionPool(host='127.0.0.1', port=32109): Max retries exceeded with url: /ticket?p=7&t=%D0%9B4 (Caused by NewConnectionError('<urllib3.connection.HTTPConnection object at 0x7f8c0ad5d580>: Failed to establish a new connection: [Errno 111] Connection refused')). 
[2025-02-04 14:00:07,320](main) Filepid(/run/user/1000/srv12.pid) exists, but the process is not started! Delete filepid
[2025-02-04 14:00:14,548](get_wplace) {"stdout": null, "stderr": "\u041e\u0448\u0438\u0431\u043a\u0430: \u043e\u0442\u0441\u0443\u0442\u0441\u0442\u0432\u0443\u0435\u0442 \u0440\u0430\u0431\u043e\u0447\u0435\u0435 \u043c\u0435\u0441\u0442\u043e. "}
[2025-02-04 14:02:23,158](main) srv12 is already running. Shutdown...
[2025-02-04 14:02:23,158](main) Filepid(/run/user/1000/srv12.pid) read error!
[2025-02-04 14:02:30,691](main) Filepid(/run/user/1000/srv12.pid) exists, but the process is not started! Delete filepid
[2025-02-04 14:02:57,578](run_tvsrv) Ошибка Инфотабло: возможно нет связи? HTTPConnectionPool(host='127.0.0.1', port=32109): Max retries exceeded with url: /ticket?p=8&t=%D0%9B7 (Caused by NewConnectionError('<urllib3.connection.HTTPConnection object at 0x7f239c3c0d00>: Failed to establish a new connection: [Errno 111] Connection refused')). 
[2025-02-04 14:04:06,968](run_tvsrv) Ошибка Инфотабло: возможно нет связи? HTTPConnectionPool(host='127.0.0.1', port=32109): Max retries exceeded with url: /ticket?p=8&t=%D0%9B7 (Caused by NewConnectionError('<urllib3.connection.HTTPConnection object at 0x7f239c3c0520>: Failed to establish a new connection: [Errno 111] Connection refused')). 
